Workbook

Sheet Constantes e Funções Auxiliares
C3: p0 | D3: p1 | E3: p2 | F3: p3 | G3: p4 | H3: p5 | I3: p6
B4: F0 | C4: 3.7
B5: F1 | C5: 8735 | D5: 22.689 | E5: 11720 | F5: 0.00978 | G5: 9306 | H5: 0.003632
B6: F2 | C6: 0.027925 | D6: 6.6577 | E6: 0.028544 | F6: 0.002455 | G6: =6.851*10^-5 -> 6.851e-05 | H6: 12.2755
B7: F3 | C7: 247970 | D7: 23.289 | E7: 374655 | F7: 0.00191 | G7: 258552
B8: F4 | C8: 0.054818 | D8: 21.032 | E8: 0.6373 | F8: 0.0791 | G8: =5.425*10^-4 -> 0.0005425
B9: F5 | C9: 39006 | D9: 15002330 | E9: 2009.24 | F9: 0.01181 | G9: 3.146 | H9: 16.7417 | I9: 3727
B10: F6 | C10: =6.031*10^-5 -> 6.031e-05 | D10: 95.5 | E10: 0.0013826
B11: F7 | C11: 11747 | D11: 55.033 | E11: 4521 | F11: 0.01998 | G11: 0.00604 | H11: 3347.4 | I11: 0.00475
B12: F8 | C12: 0.01543 | D12: 13.29 | E12: 0.01807 | F12: 0.0011 | G12: =8.81*10^-5 -> 8.81e-05 | H12: 0.0405 | I12: 26.74
B13: Fp | C13: 0.4922 | D13: 0.86
B14: Fveg | C14: 0.17 | D14: 0.41 | E14: 9.25
B15: D86 | C15: 8.321 | D15: 0.14249 | E15: 0.96655 | F15: 0.01 | G15: 20 | H15: 0.0429
B20: Hveg / m | C20: Hveg/ kgm-2 | D20: p / hPa | E20: p / mbar | F20: T / ºC | G20: H / % | H20: H / gm-3 | I20: rbulk / g cm-3 | J20: rágua / g cm-3 | K20: Fp
B21: 0.35 | C21: =B21*4.4 -> 1.54 | D21: =(995.6+994.9)/2 -> 995.25 | E21: =D21 -> 995.25 | F21: =(20.8+19.7)/2 -> 20.25 | G21: =(58.9+57.5)/2 -> 58.2 | H21: 10.21 | I21: =18/9.81 -> 1.8348624 | J21: =1 -> 1 | K21: =C13/(D13-EXP(-E21/1013)) -> 1.0135545

Sheet Medições Diretas
F4: Massa recipiente / g | H4: Massa recipiente + solo húmido /g | J4: Massa solo húmido / g | L4: Massa recipiente + solo seco / g | N4: Massa solo seco / g | P4: Massa de água / g | R4: Teor em água / % | T4: Teor em água médio / % | U4: ϑm / % | W4: ϑV / % | Z4: <θ>
A5: Amostra | B5: Cápsulas | C5: Raio / m | D5: Perfil | E5: Profundidade / cm | F5: Ensaio 1 | G5: Ensaio 2 | H5: Ensaio 1 | I5: Ensaio 2 | J5: Ensaio 1 | K5: Ensaio 2 | L5: Ensaio 1 | M5: Ensaio 2 | N5: Ensaio 1 | O5: Ensaio 2 | P5: Ensaio 1 | Q5: Ensaio 2 | R5: Ensaio 1 | S5: Ensaio 2 | U5: Ensaio 1 | V5: Ensaio 2 | W5: Ensaio 1 | X5: Ensaio 2 | Y5: Média | Z5: =AVERAGE(Y6:Y47) -> 43.313559
A6: 1.1.1 | B6: A | C6: 2 | D6: 1 | E6: 5 | F6: 10.79 | G6: 4.72 | H6: 35.75 | I6: 20.76 | J6: =H6-F6 -> 24.96 | K6: =I6-G6 -> 16.04 | L6: 29.3 | M6: 16.9 | N6: =L6-F6 -> 18.51 | O6: =M6-G6 -> 12.18 | P6: =J6-N6 -> 6.45 | Q6: =K6-O6 -> 3.86 | R6: =(P6/N6)*100 -> 34.846029 | S6: =(Q6/O6)*100 -> 31.691297 | T6: =(R6+S6)/2 -> 33.268663 | U6: =P6/N6*100 -> 34.846029 | V6: =Q6/O6*100 -> 31.691297 | W6: =(U6/'Constantes e Funções Auxiliares'!$J$21)*'Constantes e Funções Auxiliares'!$I$21 -> 63.937668 | X6: =(V6/'Constantes e Funções Auxiliares'!$J$21)*'Constantes e Funções Auxiliares'!$I$21 -> 58.149169 | Y6: =(W6+X6)/2 -> 61.043419
A7: 1.1.2 | B7: B | E7: 15 | F7: 10.51 | G7: 10.13 | H7: 36.87 | I7: 27.87 | J7: =H7-F7 -> 26.36 | K7: =I7-G7 -> 17.74 | L7: 33.08 | M7: 25.46 | N7: =L7-F7 -> 22.57 | O7: =M7-G7 -> 15.33 | P7: =J7-N7 -> 3.79 | Q7: =K7-O7 -> 2.41 | R7: =(P7/N7)*100 -> 16.792202 | S7: =(Q7/O7)*100 -> 15.720809 | T7: =(R7+S7)/2 -> 16.256505 | U7: =P7/N7*100 -> 16.792202 | V7: =Q7/O7*100 -> 15.720809 | W7: =(U7/'Constantes e Funções Auxiliares'!$J$21)*'Constantes e Funções Auxiliares'!$I$21 -> 30.81138 | X7: =(V7/'Constantes e Funções Auxiliares'!$J$21)*'Constantes e Funções Auxiliares'!$I$21 -> 28.845521 | Y7: =(W7+X7)/2 -> 29.82845
A8: 1.1.3 | B8: C | E8: 30 | F8: 11.25 | G8: 8.31 | H8: 38.76 | I8: 28.31 | J8: =H8-F8 -> 27.51 | K8: =I8-G8 -> 20 | L8: 34.4 | M8: 25.2 | N8: =L8-F8 -> 23.15 | O8: =M8-G8 -> 16.89 | P8: =J8-N8 -> 4.36 | Q8: =K8-O8 -> 3.11 | R8: =(P8/N8)*100 -> 18.833693 | S8: =(Q8/O8)*100 -> 18.413262 | T8: =(R8+S8)/2 -> 18.623478 | U8: =P8/N8*100 -> 18.833693 | V8: =Q8/O8*100 -> 18.413262 | W8: =(U8/'Constantes e Funções Auxiliares'!$J$21)*'Constantes e Funções Auxiliares'!$I$21 -> 34.557235 | X8: =(V8/'Constantes e Funções Auxiliares'!$J$21)*'Constantes e Funções Auxiliares'!$I$21 -> 33.785802 | Y8: =(W8+X8)/2 -> 34.171519
A9: 1.2.1 | B9: D | D9: 2 | E9: 5 | F9: 24.03 | G9: 4.49 | H9: 51.13 | I9: 20.31 | J9: =H9-F9 -> 27.1 | K9: =I9-G9 -> 15.82 | L9: 45.96 | M9: 17.34 | N9: =L9-F9 -> 21.93 | O9: =M9-G9 -> 12.85 | P9: =J9-N9 -> 5.17 | Q9: =K9-O9 -> 2.97 | R9: =(P9/N9)*100 -> 23.575011 | S9: =(Q9/O9)*100 -> 23.11284 | T9: =(R9+S9)/2 -> 23.343926 | U9: =P9/N9*100 -> 23.575011 | V9: =Q9/O9*100 -> 23.11284 | W9: =(U9/'Constantes e Funções Auxiliares'!$J$21)*'Constantes e Funções Auxiliares'!$I$21 -> 43.256902 | X9: =(V9/'Constantes e Funções Auxiliares'!$J$21)*'Constantes e Funções Auxiliares'!$I$21 -> 42.408882 | Y9: =(W9+X9)/2 -> 42.832892
A10: 1.2.2 | B10: E | D10: 2 | E10: 15 | F10: 20.23 | G10: 4.69 | H10: 47.27 | I10: 22.51 | J10: =H10-F10 -> 27.04 | K10: =I10-G10 -> 17.82 | L10: 42.26 | M10: 19.31 | N10: =L10-F10 -> 22.03 | O10: =M10-G10 -> 14.62 | P10: =J10-N10 -> 5.01 | Q10: =K10-O10 -> 3.2 | R10: =(P10/N10)*100 -> 22.741716 | S10: =(Q10/O10)*100 -> 21.887825 | T10: =(R10+S10)/2 -> 22.31477 | U10: =P10/N10*100 -> 22.741716 | V10: =Q10/O10*100 -> 21.887825 | W10: =(U10/'Constantes e Funções Auxiliares'!$J$21)*'Constantes e Funções Auxiliares'!$I$21 -> 41.727919 | X10: =(V10/'Constantes e Funções Auxiliares'!$J$21)*'Constantes e Funções Auxiliares'!$I$21 -> 40.161147 | Y10: =(W10+X10)/2 -> 40.944533
A11: 1.2.3 | B11: F | E11: 30 | F11: 20.58 | G11: 4.69 | H11: 49.98 | I11: 24 | J11: =H11-F11 -> 29.4 | K11: =I11-G11 -> 19.31 | L11: 45.33 | M11: 20.98 | N11: =L11-F11 -> 24.75 | O11: =M11-G11 -> 16.29 | P11: =J11-N11 -> 4.65 | Q11: =K11-O11 -> 3.02 | R11: =(P11/N11)*100 -> 18.787879 | S11: =(Q11/O11)*100 -> 18.538981 | T11: =(R11+S11)/2 -> 18.66343 | U11: =P11/N11*100 -> 18.787879 | V11: =Q11/O11*100 -> 18.538981 | W11: =(U11/'Constantes e Funções Auxiliares'!$J$21)*'Constantes e Funções Auxiliares'!$I$21 -> 34.473172 | X11: =(V11/'Constantes e Funções Auxiliares'!$J$21)*'Constantes e Funções Auxiliares'!$I$21 -> 34.016479 | Y11: =(W11+X11)/2 -> 34.244825
A12: 1.3.1 | B12: G | D12: 3 | E12: 5 | F12: 20.62 | G12: 4.54 | H12: 46.97 | I12: 22.41 | J12: =H12-F12 -> 26.35 | K12: =I12-G12 -> 17.87 | L12: 41.84 | M12: 19.95 | N12: =L12-F12 -> 21.22 | O12: =M12-G12 -> 15.41 | P12: =J12-N12 -> 5.13 | Q12: =K12-O12 -> 2.46 | R12: =(P12/N12)*100 -> 24.175306 | S12: =(Q12/O12)*100 -> 15.96366 | T12: =(R12+S12)/2 -> 20.069483 | U12: =P12/N12*100 -> 24.175306 | V12: =Q12/O12*100 -> 15.96366 | W12: =(U12/'Constantes e Funções Auxiliares'!$J$21)*'Constantes e Funções Auxiliares'!$I$21 -> 44.35836 | X12: =(V12/'Constantes e Funções Auxiliares'!$J$21)*'Constantes e Funções Auxiliares'!$I$21 -> 29.291119 | Y12: =(W12+X12)/2 -> 36.82474
A13: 1.3.2 | B13: H | D13: 3 | E13: 15 | F13: 10.32 | G13: 4.59 | H13: 42.17 | I13: 28.82 | J13: =H13-F13 -> 31.85 | K13: =I13-G13 -> 24.23 | L13: 36.54 | M13: 24.59 | N13: =L13-F13 -> 26.22 | O13: =M13-G13 -> 20 | P13: =J13-N13 -> 5.63 | Q13: =K13-O13 -> 4.23 | R13: =(P13/N13)*100 -> 21.472159 | S13: =(Q13/O13)*100 -> 21.15 | T13: =(R13+S13)/2 -> 21.311079 | U13: =P13/N13*100 -> 21.472159 | V13: =Q13/O13*100 -> 21.15 | W13: =(U13/'Constantes e Funções Auxiliares'!$J$21)*'Constantes e Funções Auxiliares'!$I$21 -> 39.398456 | X13: =(V13/'Constantes e Funções Auxiliares'!$J$21)*'Constantes e Funções Auxiliares'!$I$21 -> 38.807339 | Y13: =(W13+X13)/2 -> 39.102898
A14: 1.3.3 | B14: I | E14: 30 | F14: 10.16 | G14: 9.2 | H14: 39.4 | I14: 38.86 | J14: =H14-F14 -> 29.24 | K14: =I14-G14 -> 29.66 | L14: 35.18 | M14: 34.57 | N14: =L14-F14 -> 25.02 | O14: =M14-G14 -> 25.37 | P14: =J14-N14 -> 4.22 | Q14: =K14-O14 -> 4.29 | R14: =(P14/N14)*100 -> 16.866507 | S14: =(Q14/O14)*100 -> 16.909736 | T14: =(R14+S14)/2 -> 16.888121 | U14: =P14/N14*100 -> 16.866507 | V14: =Q14/O14*100 -> 16.909736 | W14: =(U14/'Constantes e Funções Auxiliares'!$J$21)*'Constantes e Funções Auxiliares'!$I$21 -> 30.947719 | X14: =(V14/'Constantes e Funções Auxiliares'!$J$21)*'Constantes e Funções Auxiliares'!$I$21 -> 31.027038 | Y14: =(W14+X14)/2 -> 30.987379
A15: 1.4.1 | B15: J | D15: 4 | E15: 5 | F15: 21.08 | G15: 4.38 | H15: 46.45 | I15: 29.7 | J15: =H15-F15 -> 25.37 | K15: =I15-G15 -> 25.32 | L15: 41.76 | M15: 24.69 | N15: =L15-F15 -> 20.68 | O15: =M15-G15 -> 20.31 | P15: =J15-N15 -> 4.69 | Q15: =K15-O15 -> 5.01 | R15: =(P15/N15)*100 -> 22.678917 | S15: =(Q15/O15)*100 -> 24.667651 | T15: =(R15+S15)/2 -> 23.673284 | U15: =P15/N15*100 -> 22.678917 | V15: =Q15/O15*100 -> 24.667651 | W15: =(U15/'Constantes e Funções Auxiliares'!$J$21)*'Constantes e Funções Auxiliares'!$I$21 -> 41.612691 | X15: =(V15/'Constantes e Funções Auxiliares'!$J$21)*'Constantes e Funções Auxiliares'!$I$21 -> 45.261746 | Y15: =(W15+X15)/2 -> 43.437219
A16: 1.4.2 | B16: K | D16: 4 | E16: 15 | F16: 10.82 | G16: 4.54 | H16: 40.45 | I16: 25.46 | J16: =H16-F16 -> 29.63 | K16: =I16-G16 -> 20.92 | L16: 34.48 | M16: 21.09 | N16: =L16-F16 -> 23.66 | O16: =M16-G16 -> 16.55 | P16: =J16-N16 -> 5.97 | Q16: =K16-O16 -> 4.37 | R16: =(P16/N16)*100 -> 25.23246 | S16: =(Q16/O16)*100 -> 26.404834 | T16: =(R16+S16)/2 -> 25.818647 | U16: =P16/N16*100 -> 25.23246 | V16: =Q16/O16*100 -> 26.404834 | W16: =(U16/'Constantes e Funções Auxiliares'!$J$21)*'Constantes e Funções Auxiliares'!$I$21 -> 46.298091 | X16: =(V16/'Constantes e Funções Auxiliares'!$J$21)*'Constantes e Funções Auxiliares'!$I$21 -> 48.449236 | Y16: =(W16+X16)/2 -> 47.373664
A17: 1.4.3 | B17: L | E17: 30 | F17: 20.65 | G17: 8.09 | H17: 43.56 | I17: 33.96 | J17: =H17-F17 -> 22.91 | K17: =I17-G17 -> 25.87 | L17: 40.54 | M17: 30.52 | N17: =L17-F17 -> 19.89 | O17: =M17-G17 -> 22.43 | P17: =J17-N17 -> 3.02 | Q17: =K17-O17 -> 3.44 | R17: =(P17/N17)*100 -> 15.183509 | S17: =(Q17/O17)*100 -> 15.336603 | T17: =(R17+S17)/2 -> 15.260056 | U17: =P17/N17*100 -> 15.183509 | V17: =Q17/O17*100 -> 15.336603 | W17: =(U17/'Constantes e Funções Auxiliares'!$J$21)*'Constantes e Funções Auxiliares'!$I$21 -> 27.85965 | X17: =(V17/'Constantes e Funções Auxiliares'!$J$21)*'Constantes e Funções Auxiliares'!$I$21 -> 28.140556 | Y17: =(W17+X17)/2 -> 28.000103
A18: 1.5.1 | B18: M | D18: 5 | E18: 5 | F18: 18.15 | G18: 14.76 | H18: 44.67 | I18: 39.45 | J18: =H18-F18 -> 26.52 | K18: =I18-G18 -> 24.69 | L18: 39.07 | M18: 34.31 | N18: =L18-F18 -> 20.92 | O18: =M18-G18 -> 19.55 | P18: =J18-N18 -> 5.6 | Q18: =K18-O18 -> 5.14 | R18: =(P18/N18)*100 -> 26.768642 | S18: =(Q18/O18)*100 -> 26.29156 | T18: =(R18+S18)/2 -> 26.530101 | U18: =P18/N18*100 -> 26.768642 | V18: =Q18/O18*100 -> 26.29156 | W18: =(U18/'Constantes e Funções Auxiliares'!$J$21)*'Constantes e Funções Auxiliares'!$I$21 -> 49.116775 | X18: =(V18/'Constantes e Funções Auxiliares'!$J$21)*'Constantes e Funções Auxiliares'!$I$21 -> 48.241395 | Y18: =(W18+X18)/2 -> 48.679085
A19: 1.5.2 | B19: N | D19: 5 | E19: 15 | F19: 20.98 | G19: 4.65 | H19: 44.27 | I19: 26.61 | J19: =H19-F19 -> 23.29 | K19: =I19-G19 -> 21.96 | L19: 39.65 | M19: 22.39 | N19: =L19-F19 -> 18.67 | O19: =M19-G19 -> 17.74 | P19: =J19-N19 -> 4.62 | Q19: =K19-O19 -> 4.22 | R19: =(P19/N19)*100 -> 24.745581 | S19: =(Q19/O19)*100 -> 23.78805 | T19: =(R19+S19)/2 -> 24.266815 | U19: =P19/N19*100 -> 24.745581 | V19: =Q19/O19*100 -> 23.78805 | W19: =(U19/'Constantes e Funções Auxiliares'!$J$21)*'Constantes e Funções Auxiliares'!$I$21 -> 45.404736 | X19: =(V19/'Constantes e Funções Auxiliares'!$J$21)*'Constantes e Funções Auxiliares'!$I$21 -> 43.647797 | Y19: =(W19+X19)/2 -> 44.526267
A20: 1.5.3 | B20: O | E20: 30 | F20: 11.02 | G20: 4.43 | H20: 35.96 | I20: 23.09 | J20: =H20-F20 -> 24.94 | K20: =I20-G20 -> 18.66 | L20: 32.03 | M20: 19.86 | N20: =L20-F20 -> 21.01 | O20: =M20-G20 -> 15.43 | P20: =J20-N20 -> 3.93 | Q20: =K20-O20 -> 3.23 | R20: =(P20/N20)*100 -> 18.705378 | S20: =(Q20/O20)*100 -> 20.933247 | T20: =(R20+S20)/2 -> 19.819313 | U20: =P20/N20*100 -> 18.705378 | V20: =Q20/O20*100 -> 20.933247 | W20: =(U20/'Constantes e Funções Auxiliares'!$J$21)*'Constantes e Funções Auxiliares'!$I$21 -> 34.321795 | X20: =(V20/'Constantes e Funções Auxiliares'!$J$21)*'Constantes e Funções Auxiliares'!$I$21 -> 38.409627 | Y20: =(W20+X20)/2 -> 36.365711
A21: 1.6.1 | B21: P | D21: 6 | E21: 5 | F21: 10 | G21: 14.56 | H21: 35.04 | I21: 34.24 | J21: =H21-F21 -> 25.04 | K21: =I21-G21 -> 19.68 | L21: 30.03 | M21: 30.51 | N21: =L21-F21 -> 20.03 | O21: =M21-G21 -> 15.95 | P21: =J21-N21 -> 5.01 | Q21: =K21-O21 -> 3.73 | R21: =(P21/N21)*100 -> 25.012481 | S21: =(Q21/O21)*100 -> 23.38558 | T21: =(R21+S21)/2 -> 24.199031 | U21: =P21/N21*100 -> 25.012481 | V21: =Q21/O21*100 -> 23.38558 | W21: =(U21/'Constantes e Funções Auxiliares'!$J$21)*'Constantes e Funções Auxiliares'!$I$21 -> 45.894461 | X21: =(V21/'Constantes e Funções Auxiliares'!$J$21)*'Constantes e Funções Auxiliares'!$I$21 -> 42.909321 | Y21: =(W21+X21)/2 -> 44.401891
A22: 1.6.2 | B22: Q | D22: 6 | E22: 15 | F22: 22.99 | G22: 4.63 | H22: 49.07 | I22: 24.81 | J22: =H22-F22 -> 26.08 | K22: =I22-G22 -> 20.18 | L22: 44.76 | M22: 21.64 | N22: =L22-F22 -> 21.77 | O22: =M22-G22 -> 17.01 | P22: =J22-N22 -> 4.31 | Q22: =K22-O22 -> 3.17 | R22: =(P22/N22)*100 -> 19.797887 | S22: =(Q22/O22)*100 -> 18.636096 | T22: =(R22+S22)/2 -> 19.216992 | U22: =P22/N22*100 -> 19.797887 | V22: =Q22/O22*100 -> 18.636096 | W22: =(U22/'Constantes e Funções Auxiliares'!$J$21)*'Constantes e Funções Auxiliares'!$I$21 -> 36.326398 | X22: =(V22/'Constantes e Funções Auxiliares'!$J$21)*'Constantes e Funções Auxiliares'!$I$21 -> 34.194672 | Y22: =(W22+X22)/2 -> 35.260535
A23: 1.6.3 | B23: R | E23: 30 | F23: 10.79 | G23: 4.73 | H23: 36.98 | I23: 27 | J23: =H23-F23 -> 26.19 | K23: =I23-G23 -> 22.27 | L23: 33.04 | M23: 23.72 | N23: =L23-F23 -> 22.25 | O23: =M23-G23 -> 18.99 | P23: =J23-N23 -> 3.94 | Q23: =K23-O23 -> 3.28 | R23: =(P23/N23)*100 -> 17.707865 | S23: =(Q23/O23)*100 -> 17.272249 | T23: =(R23+S23)/2 -> 17.490057 | U23: =P23/N23*100 -> 17.707865 | V23: =Q23/O23*100 -> 17.272249 | W23: =(U23/'Constantes e Funções Auxiliares'!$J$21)*'Constantes e Funções Auxiliares'!$I$21 -> 32.491496 | X23: =(V23/'Constantes e Funções Auxiliares'!$J$21)*'Constantes e Funções Auxiliares'!$I$21 -> 31.692199 | Y23: =(W23+X23)/2 -> 32.091847
A24: 2.1.1 | B24: S | C24: 20 | D24: 1 | E24: 5 | F24: 21.11 | G24: 8.95 | H24: 44.72 | I24: 26.53 | J24: =H24-F24 -> 23.61 | K24: =I24-G24 -> 17.58 | L24: 39.61 | M24: 22.63 | N24: =L24-F24 -> 18.5 | O24: =M24-G24 -> 13.68 | P24: =J24-N24 -> 5.11 | Q24: =K24-O24 -> 3.9 | R24: =(P24/N24)*100 -> 27.621622 | S24: =(Q24/O24)*100 -> 28.508772 | T24: =(R24+S24)/2 -> 28.065197 | U24: =P24/N24*100 -> 27.621622 | V24: =Q24/O24*100 -> 28.508772 | W24: =(U24/'Constantes e Funções Auxiliares'!$J$21)*'Constantes e Funções Auxiliares'!$I$21 -> 50.681875 | X24: =(V24/'Constantes e Funções Auxiliares'!$J$21)*'Constantes e Funções Auxiliares'!$I$21 -> 52.309673 | Y24: =(W24+X24)/2 -> 51.495774
A25: 2.1.2 | B25: U | E25: 15 | F25: 10.51 | G25: 4.57 | H25: 36.32 | I25: 23.71 | J25: =H25-F25 -> 25.81 | K25: =I25-G25 -> 19.14 | L25: 32.25 | M25: 20.84 | N25: =L25-F25 -> 21.74 | O25: =M25-G25 -> 16.27 | P25: =J25-N25 -> 4.07 | Q25: =K25-O25 -> 2.87 | R25: =(P25/N25)*100 -> 18.721251 | S25: =(Q25/O25)*100 -> 17.639828 | T25: =(R25+S25)/2 -> 18.18054 | U25: =P25/N25*100 -> 18.721251 | V25: =Q25/O25*100 -> 17.639828 | W25: =(U25/'Constantes e Funções Auxiliares'!$J$21)*'Constantes e Funções Auxiliares'!$I$21 -> 34.35092 | X25: =(V25/'Constantes e Funções Auxiliares'!$J$21)*'Constantes e Funções Auxiliares'!$I$21 -> 32.366657 | Y25: =(W25+X25)/2 -> 33.358788
A26: 2.1.3 | B26: T | E26: 30 | F26: 10.52 | G26: 9.09 | H26: 37.68 | I26: 28.99 | J26: =H26-F26 -> 27.16 | K26: =I26-G26 -> 19.9 | L26: 33.83 | M26: 26.21 | N26: =L26-F26 -> 23.31 | O26: =M26-G26 -> 17.12 | P26: =J26-N26 -> 3.85 | Q26: =K26-O26 -> 2.78 | R26: =(P26/N26)*100 -> 16.516517 | S26: =(Q26/O26)*100 -> 16.238318 | T26: =(R26+S26)/2 -> 16.377417 | U26: =P26/N26*100 -> 16.516517 | V26: =Q26/O26*100 -> 16.238318 | W26: =(U26/'Constantes e Funções Auxiliares'!$J$21)*'Constantes e Funções Auxiliares'!$I$21 -> 30.305535 | X26: =(V26/'Constantes e Funções Auxiliares'!$J$21)*'Constantes e Funções Auxiliares'!$I$21 -> 29.795078 | Y26: =(W26+X26)/2 -> 30.050307
A27: 2.2.1 | B27: V | D27: 2 | E27: 5 | F27: 10.9 | G27: 4.23 | H27: 38.66 | I27: 23.43 | J27: =H27-F27 -> 27.76 | K27: =I27-G27 -> 19.2 | L27: 32.32 | M27: 19.14 | N27: =L27-F27 -> 21.42 | O27: =M27-G27 -> 14.91 | P27: =J27-N27 -> 6.34 | Q27: =K27-O27 -> 4.29 | R27: =(P27/N27)*100 -> 29.598506 | S27: =(Q27/O27)*100 -> 28.772636 | T27: =(R27+S27)/2 -> 29.185571 | U27: =P27/N27*100 -> 29.598506 | V27: =Q27/O27*100 -> 28.772636 | W27: =(U27/'Constantes e Funções Auxiliares'!$J$21)*'Constantes e Funções Auxiliares'!$I$21 -> 54.309185 | X27: =(V27/'Constantes e Funções Auxiliares'!$J$21)*'Constantes e Funções Auxiliares'!$I$21 -> 52.793827 | Y27: =(W27+X27)/2 -> 53.551506
A28: 2.2.2 | B28: W | E28: 15 | F28: 20.25 | G28: 20.74 | H28: 47.31 | I28: 44.87 | J28: =H28-F28 -> 27.06 | K28: =I28-G28 -> 24.13 | L28: 40.63 | M28: 42.82 | N28: =L28-F28 -> 20.38 | O28: =M28-G28 -> 22.08 | P28: =J28-N28 -> 6.68 | Q28: =K28-O28 -> 2.05 | R28: =(P28/N28)*100 -> 32.777233 | S28: =(Q28/O28)*100 -> 9.2844203 | T28: =(R28+S28)/2 -> 21.030826 | U28: =P28/N28*100 -> 32.777233 | V28: =Q28/O28*100 -> 9.2844203 | W28: =(U28/'Constantes e Funções Auxiliares'!$J$21)*'Constantes e Funções Auxiliares'!$I$21 -> 60.141711 | X28: =(V28/'Constantes e Funções Auxiliares'!$J$21)*'Constantes e Funções Auxiliares'!$I$21 -> 17.035634 | Y28: =(W28+X28)/2 -> 38.588672
A29: 2.2.3 | B29: X | E29: 30 | F29: 20.74 | G29: 9.29 | H29: 47.28 | I29: 36.49 | J29: =H29-F29 -> 26.54 | K29: =I29-G29 -> 27.2 | L29: 42.62 | M29: 30.97 | N29: =L29-F29 -> 21.88 | O29: =M29-G29 -> 21.68 | P29: =J29-N29 -> 4.66 | Q29: =K29-O29 -> 5.52 | R29: =(P29/N29)*100 -> 21.297989 | S29: =(Q29/O29)*100 -> 25.461255 | T29: =(R29+S29)/2 -> 23.379622 | U29: =P29/N29*100 -> 21.297989 | V29: =Q29/O29*100 -> 25.461255 | W29: =(U29/'Constantes e Funções Auxiliares'!$J$21)*'Constantes e Funções Auxiliares'!$I$21 -> 39.078879 | X29: =(V29/'Constantes e Funções Auxiliares'!$J$21)*'Constantes e Funções Auxiliares'!$I$21 -> 46.717898 | Y29: =(W29+X29)/2 -> 42.898389
A30: 2.3.1 | B30: Y | D30: 3 | E30: 5 | F30: 21.01 | G30: 8.89 | H30: 45.42 | I30: 34.73 | J30: =H30-F30 -> 24.41 | K30: =I30-G30 -> 25.84 | L30: 40.01 | M30: 29.06 | N30: =L30-F30 -> 19 | O30: =M30-G30 -> 20.17 | P30: =J30-N30 -> 5.41 | Q30: =K30-O30 -> 5.67 | R30: =(P30/N30)*100 -> 28.473684 | S30: =(Q30/O30)*100 -> 28.111056 | T30: =(R30+S30)/2 -> 28.29237 | U30: =P30/N30*100 -> 28.473684 | V30: =Q30/O30*100 -> 28.111056 | W30: =(U30/'Constantes e Funções Auxiliares'!$J$21)*'Constantes e Funções Auxiliares'!$I$21 -> 52.245292 | X30: =(V30/'Constantes e Funções Auxiliares'!$J$21)*'Constantes e Funções Auxiliares'!$I$21 -> 51.579919 | Y30: =(W30+X30)/2 -> 51.912606
A31: 2.3.2 | B31: Z | E31: 15 | F31: 20.48 | G31: 11.25 | H31: 45.1 | I31: 36.81 | J31: =H31-F31 -> 24.62 | K31: =I31-G31 -> 25.56 | L31: 40.79 | M31: 32.38 | N31: =L31-F31 -> 20.31 | O31: =M31-G31 -> 21.13 | P31: =J31-N31 -> 4.31 | Q31: =K31-O31 -> 4.43 | R31: =(P31/N31)*100 -> 21.221073 | S31: =(Q31/O31)*100 -> 20.965452 | T31: =(R31+S31)/2 -> 21.093263 | U31: =P31/N31*100 -> 21.221073 | V31: =Q31/O31*100 -> 20.965452 | W31: =(U31/'Constantes e Funções Auxiliares'!$J$21)*'Constantes e Funções Auxiliares'!$I$21 -> 38.937749 | X31: =(V31/'Constantes e Funções Auxiliares'!$J$21)*'Constantes e Funções Auxiliares'!$I$21 -> 38.468719 | Y31: =(W31+X31)/2 -> 38.703234
A32: 2.3.3 | B32: 1 | E32: 30 | F32: 11.16 | G32: 11.25 | H32: 32.16 | I32: 36.13 | J32: =H32-F32 -> 21 | K32: =I32-G32 -> 24.88 | L32: 28.68 | M32: 31.86 | N32: =L32-F32 -> 17.52 | O32: =M32-G32 -> 20.61 | P32: =J32-N32 -> 3.48 | Q32: =K32-O32 -> 4.27 | R32: =(P32/N32)*100 -> 19.863014 | S32: =(Q32/O32)*100 -> 20.718098 | T32: =(R32+S32)/2 -> 20.290556 | U32: =P32/N32*100 -> 19.863014 | V32: =Q32/O32*100 -> 20.718098 | W32: =(U32/'Constantes e Funções Auxiliares'!$J$21)*'Constantes e Funções Auxiliares'!$I$21 -> 36.445897 | X32: =(V32/'Constantes e Funções Auxiliares'!$J$21)*'Constantes e Funções Auxiliares'!$I$21 -> 38.014859 | Y32: =(W32+X32)/2 -> 37.230378
A33: 2.4.1 | B33: 2 | D33: 4 | E33: 5 | F33: 11.07 | G33: 8.77 | H33: 34.82 | I33: 34.14 | J33: =H33-F33 -> 23.75 | K33: =I33-G33 -> 25.37 | L33: 29.49 | M33: 28.4 | N33: =L33-F33 -> 18.42 | O33: =M33-G33 -> 19.63 | P33: =J33-N33 -> 5.33 | Q33: =K33-O33 -> 5.74 | R33: =(P33/N33)*100 -> 28.935939 | S33: =(Q33/O33)*100 -> 29.240958 | T33: =(R33+S33)/2 -> 29.088448 | U33: =P33/N33*100 -> 28.935939 | V33: =Q33/O33*100 -> 29.240958 | W33: =(U33/'Constantes e Funções Auxiliares'!$J$21)*'Constantes e Funções Auxiliares'!$I$21 -> 53.093466 | X33: =(V33/'Constantes e Funções Auxiliares'!$J$21)*'Constantes e Funções Auxiliares'!$I$21 -> 53.653133 | Y33: =(W33+X33)/2 -> 53.3733
A34: 2.4.2 | B34: 3 | E34: 15 | F34: 11.03 | G34: 11.16 | H34: 35.34 | I34: 34.94 | J34: =H34-F34 -> 24.31 | K34: =I34-G34 -> 23.78 | L34: 29.94 | M34: 29.34 | N34: =L34-F34 -> 18.91 | O34: =M34-G34 -> 18.18 | P34: =J34-N34 -> 5.4 | Q34: =K34-O34 -> 5.6 | R34: =(P34/N34)*100 -> 28.556319 | S34: =(Q34/O34)*100 -> 30.80308 | T34: =(R34+S34)/2 -> 29.6797 | U34: =P34/N34*100 -> 28.556319 | V34: =Q34/O34*100 -> 30.80308 | W34: =(U34/'Constantes e Funções Auxiliares'!$J$21)*'Constantes e Funções Auxiliares'!$I$21 -> 52.396916 | X34: =(V34/'Constantes e Funções Auxiliares'!$J$21)*'Constantes e Funções Auxiliares'!$I$21 -> 56.519413 | Y34: =(W34+X34)/2 -> 54.458165
A35: 2.4.3 | B35: 4 | E35: 30 | F35: 11.13 | G35: 11.26 | H35: 35.54 | I35: 37.51 | J35: =H35-F35 -> 24.41 | K35: =I35-G35 -> 26.25 | L35: 31.42 | M35: 33.2 | N35: =L35-F35 -> 20.29 | O35: =M35-G35 -> 21.94 | P35: =J35-N35 -> 4.12 | Q35: =K35-O35 -> 4.31 | R35: =(P35/N35)*100 -> 20.305569 | S35: =(Q35/O35)*100 -> 19.644485 | T35: =(R35+S35)/2 -> 19.975027 | U35: =P35/N35*100 -> 20.305569 | V35: =Q35/O35*100 -> 19.644485 | W35: =(U35/'Constantes e Funções Auxiliares'!$J$21)*'Constantes e Funções Auxiliares'!$I$21 -> 37.257925 | X35: =(V35/'Constantes e Funções Auxiliares'!$J$21)*'Constantes e Funções Auxiliares'!$I$21 -> 36.044927 | Y35: =(W35+X35)/2 -> 36.651426
A36: 2.5.1 | B36: 5 | D36: 5 | E36: 5 | F36: 11.13 | G36: 10.22 | H36: 34.55 | I36: 35.72 | J36: =H36-F36 -> 23.42 | K36: =I36-G36 -> 25.5 | L36: 28.36 | M36: 29.09 | N36: =L36-F36 -> 17.23 | O36: =M36-G36 -> 18.87 | P36: =J36-N36 -> 6.19 | Q36: =K36-O36 -> 6.63 | R36: =(P36/N36)*100 -> 35.925711 | S36: =(Q36/O36)*100 -> 35.135135 | T36: =(R36+S36)/2 -> 35.530423 | U36: =P36/N36*100 -> 35.925711 | V36: =Q36/O36*100 -> 35.135135 | W36: =(U36/'Constantes e Funções Auxiliares'!$J$21)*'Constantes e Funções Auxiliares'!$I$21 -> 65.918736 | X36: =(V36/'Constantes e Funções Auxiliares'!$J$21)*'Constantes e Funções Auxiliares'!$I$21 -> 64.468138 | Y36: =(W36+X36)/2 -> 65.193437
A37: 2.5.2 | B37: 6 | E37: 15 | F37: 10.55 | G37: 20.96 | H37: 36.5 | I37: 45.05 | J37: =H37-F37 -> 25.95 | K37: =I37-G37 -> 24.09 | L37: 31.39 | M37: 40.41 | N37: =L37-F37 -> 20.84 | O37: =M37-G37 -> 19.45 | P37: =J37-N37 -> 5.11 | Q37: =K37-O37 -> 4.64 | R37: =(P37/N37)*100 -> 24.520154 | S37: =(Q37/O37)*100 -> 23.856041 | T37: =(R37+S37)/2 -> 24.188097 | U37: =P37/N37*100 -> 24.520154 | V37: =Q37/O37*100 -> 23.856041 | W37: =(U37/'Constantes e Funções Auxiliares'!$J$21)*'Constantes e Funções Auxiliares'!$I$21 -> 44.991107 | X37: =(V37/'Constantes e Funções Auxiliares'!$J$21)*'Constantes e Funções Auxiliares'!$I$21 -> 43.772553 | Y37: =(W37+X37)/2 -> 44.38183
A38: 2.5.3 | B38: 7 | E38: 30 | F38: 10.96 | G38: 20.91 | H38: 34.07 | I38: 46.87 | J38: =H38-F38 -> 23.11 | K38: =I38-G38 -> 25.96 | L38: 29.42 | M38: 41.73 | N38: =L38-F38 -> 18.46 | O38: =M38-G38 -> 20.82 | P38: =J38-N38 -> 4.65 | Q38: =K38-O38 -> 5.14 | R38: =(P38/N38)*100 -> 25.189599 | S38: =(Q38/O38)*100 -> 24.6878 | T38: =(R38+S38)/2 -> 24.9387 | U38: =P38/N38*100 -> 25.189599 | V38: =Q38/O38*100 -> 24.6878 | W38: =(U38/'Constantes e Funções Auxiliares'!$J$21)*'Constantes e Funções Auxiliares'!$I$21 -> 46.219448 | X38: =(V38/'Constantes e Funções Auxiliares'!$J$21)*'Constantes e Funções Auxiliares'!$I$21 -> 45.298716 | Y38: =(W38+X38)/2 -> 45.759082
A39: 3.1.1 | B39: 8 | C39: 50 | D39: 1 | E39: 5 | F39: 8.81 | G39: 11.89 | H39: 33.84 | I39: 36.25 | J39: =H39-F39 -> 25.03 | K39: =I39-G39 -> 24.36 | L39: 27.21 | M39: 29.95 | N39: =L39-F39 -> 18.4 | O39: =M39-G39 -> 18.06 | P39: =J39-N39 -> 6.63 | Q39: =K39-O39 -> 6.3 | R39: =(P39/N39)*100 -> 36.032609 | S39: =(Q39/O39)*100 -> 34.883721 | T39: =(R39+S39)/2 -> 35.458165 | U39: =P39/N39*100 -> 36.032609 | V39: =Q39/O39*100 -> 34.883721 | W39: =(U39/'Constantes e Funções Auxiliares'!$J$21)*'Constantes e Funções Auxiliares'!$I$21 -> 66.114878 | X39: =(V39/'Constantes e Funções Auxiliares'!$J$21)*'Constantes e Funções Auxiliares'!$I$21 -> 64.006827 | Y39: =(W39+X39)/2 -> 65.060853
A40: 3.1.2 | B40: 9 | E40: 15 | F40: 23.68 | G40: 10.8 | H40: 48.24 | I40: 34.76 | J40: =H40-F40 -> 24.56 | K40: =I40-G40 -> 23.96 | L40: 43.64 | M40: 30.34 | N40: =L40-F40 -> 19.96 | O40: =M40-G40 -> 19.54 | P40: =J40-N40 -> 4.6 | Q40: =K40-O40 -> 4.42 | R40: =(P40/N40)*100 -> 23.046092 | S40: =(Q40/O40)*100 -> 22.620266 | T40: =(R40+S40)/2 -> 22.833179 | U40: =P40/N40*100 -> 23.046092 | V40: =Q40/O40*100 -> 22.620266 | W40: =(U40/'Constantes e Funções Auxiliares'!$J$21)*'Constantes e Funções Auxiliares'!$I$21 -> 42.286408 | X40: =(V40/'Constantes e Funções Auxiliares'!$J$21)*'Constantes e Funções Auxiliares'!$I$21 -> 41.505075 | Y40: =(W40+X40)/2 -> 41.895742
A41: 3.1.3 | B41: 10 | E41: 30 | F41: 8.78 | G41: 11.1 | H41: 34.66 | I41: 37.71 | J41: =H41-F41 -> 25.88 | K41: =I41-G41 -> 26.61 | L41: 29.88 | M41: 32.92 | N41: =L41-F41 -> 21.1 | O41: =M41-G41 -> 21.82 | P41: =J41-N41 -> 4.78 | Q41: =K41-O41 -> 4.79 | R41: =(P41/N41)*100 -> 22.654028 | S41: =(Q41/O41)*100 -> 21.952337 | T41: =(R41+S41)/2 -> 22.303183 | U41: =P41/N41*100 -> 22.654028 | V41: =Q41/O41*100 -> 21.952337 | W41: =(U41/'Constantes e Funções Auxiliares'!$J$21)*'Constantes e Funções Auxiliares'!$I$21 -> 41.567025 | X41: =(V41/'Constantes e Funções Auxiliares'!$J$21)*'Constantes e Funções Auxiliares'!$I$21 -> 40.279518 | Y41: =(W41+X41)/2 -> 40.923271
A42: 3.2.1 | B42: 11 | D42: 2 | E42: 5 | F42: 17.41 | G42: 18.03 | H42: 42.12 | I42: 45.32 | J42: =H42-F42 -> 24.71 | K42: =I42-G42 -> 27.29 | L42: 36.66 | M42: 38.93 | N42: =L42-F42 -> 19.25 | O42: =M42-G42 -> 20.9 | P42: =J42-N42 -> 5.46 | Q42: =K42-O42 -> 6.39 | R42: =(P42/N42)*100 -> 28.363636 | S42: =(Q42/O42)*100 -> 30.574163 | T42: =(R42+S42)/2 -> 29.4689 | U42: =P42/N42*100 -> 28.363636 | V42: =Q42/O42*100 -> 30.574163 | W42: =(U42/'Constantes e Funções Auxiliares'!$J$21)*'Constantes e Funções Auxiliares'!$I$21 -> 52.043369 | X42: =(V42/'Constantes e Funções Auxiliares'!$J$21)*'Constantes e Funções Auxiliares'!$I$21 -> 56.099381 | Y42: =(W42+X42)/2 -> 54.071375
A43: 3.2.2 | B43: 12 | E43: 15 | F43: 17.74 | G43: 17.33 | H43: 45.36 | I43: 40.43 | J43: =H43-F43 -> 27.62 | K43: =I43-G43 -> 23.1 | L43: 40.39 | M43: 36.28 | N43: =L43-F43 -> 22.65 | O43: =M43-G43 -> 18.95 | P43: =J43-N43 -> 4.97 | Q43: =K43-O43 -> 4.15 | R43: =(P43/N43)*100 -> 21.942605 | S43: =(Q43/O43)*100 -> 21.899736 | T43: =(R43+S43)/2 -> 21.921171 | U43: =P43/N43*100 -> 21.942605 | V43: =Q43/O43*100 -> 21.899736 | W43: =(U43/'Constantes e Funções Auxiliares'!$J$21)*'Constantes e Funções Auxiliares'!$I$21 -> 40.26166 | X43: =(V43/'Constantes e Funções Auxiliares'!$J$21)*'Constantes e Funções Auxiliares'!$I$21 -> 40.183002 | Y43: =(W43+X43)/2 -> 40.222331
...

Sheet Ponderação Vertical
AG5: =(-5)^AC41 -> #NUM!
A6: Amostra | B6: Cápsulas | C6: Raio / m | D6: Perfil | E6: Profundidade / cm | F6: ϑV / % | G6: ϑV | H6: F7 | I6: F8 | J6: F9 | K6: F10 | L6: F11 | M6: F12 | N6: Wd (r, ϑ) | O6: ϑV * Wd (r, ϑ) | P6: ∑ (ϑV * Wd (r, ϑ)) | Q6: ∑ (Wd (r, ϑ)) | R6: θp
A7: 1.1.1 | B7: A | C7: 2 | D7: 1 | E7: 5 | F7: 61.043419 | G7: =F7/100 -> 0.61043419 | H7: =$U$28*G7^$V$28 -> -154.62446 | I7: =$U$29*G7+$V$29 -> -0.85705646 | J7: =$U$30*G7+$V$30 -> 5.4945525 | K7: =$U$31*G7^$V$31 -> 1.0153719 | L7: =$U$32*G7^$V$32 -> 0.070262122 | M7: =$U$33*G7^$V$33 -> -154.98549 | N7: =(E7^H7)*(EXP(J7*E7*(-(E7^I7)))+(K7/E7))^(E7*L7+M7) -> 0.045194017 | O7: =N7*G7 -> 0.027587973 | P7: =SUM(O7:O9) -> 0.032286031 | Q7: =SUM(N7:N9) -> 0.060765164 | R7: =P7/Q7 -> 0.53132467
A8: 1.1.2 | B8: B | E8: 15 | F8: 29.82845 | G8: =F8/100 -> 0.2982845 | H8: =$U$28*G8^$V$28 -> -141.52948 | I8: =$U$29*G8+$V$29 -> -0.82365644 | J8: =$U$30*G8+$V$30 -> 5.3414868 | K8: =$U$31*G8^$V$31 -> 1.0207524 | L8: =$U$32*G8^$V$32 -> 0.039693009 | M8: =$U$33*G8^$V$33 -> -141.76752 | N8: =(E8^H8)*(EXP(J8*E8*(-(E8^I8)))+(K8/E8))^(E8*L8+M8) -> 0.014341006 | O8: =N8*G8 -> 0.0042776999
A9: 1.1.3 | B9: C | E9: 30 | F9: 34.171519 | G9: =F9/100 -> 0.34171519 | H9: =$U$28*G9^$V$28 -> -143.92681 | I9: =$U$29*G9+$V$29 -> -0.82830353 | J9: =$U$30*G9+$V$30 -> 5.3627835 | K9: =$U$31*G9^$V$31 -> 1.0197289 | L9: =$U$32*G9^$V$32 -> 0.044237358 | M9: =$U$33*G9^$V$33 -> -144.18671 | N9: =(E9^H9)*(EXP(J9*E9*(-(E9^I9)))+(K9/E9))^(E9*L9+M9) -> 0.0012301405 | O9: =N9*G9 -> 0.00042035769
A10: 1.2.1 | B10: D | D10: 2 | E10: 5 | F10: 42.832892 | G10: =F10/100 -> 0.42832892 | H10: =$U$28*G10^$V$28 -> -148.0013 | I10: =$U$29*G10+$V$29 -> -0.83757119 | J10: =$U$30*G10+$V$30 -> 5.4052554 | K10: =$U$31*G10^$V$31 -> 1.0180302 | L10: =$U$32*G10^$V$32 -> 0.052969701 | M10: =$U$33*G10^$V$33 -> -148.29905 | N10: =(E10^H10)*(EXP(J10*E10*(-(E10^I10)))+(K10/E10))^(E10*L10+M10) -> 0.039137253 | O10: =N10*G10 -> 0.016763617 | P10: =SUM(O10:O12) -> 0.022038756 | Q10: =SUM(N10:N12) -> 0.052221039 | R10: =P10/Q10 -> 0.42202829
A11: 1.2.2 | B11: E | D11: 2 | E11: 15 | F11: 40.944533 | G11: =F11/100 -> 0.40944533 | H11: =$U$28*G11^$V$28 -> -147.179 | I11: =$U$29*G11+$V$29 -> -0.83555065 | J11: =$U$30*G11+$V$30 -> 5.3959956 | K11: =$U$31*G11^$V$31 -> 1.018369 | L11: =$U$32*G11^$V$32 -> 0.051099031 | M11: =$U$33*G11^$V$33 -> -147.46904 | N11: =(E11^H11)*(EXP(J11*E11*(-(E11^I11)))+(K11/E11))^(E11*L11+M11) -> 0.011860502 | O11: =N11*G11 -> 0.0048562273
A12: 1.2.3 | B12: F | E12: 30 | F12: 34.244825 | G12: =F12/100 -> 0.34244825 | H12: =$U$28*G12^$V$28 -> -143.96493 | I12: =$U$29*G12+$V$29 -> -0.82838196 | J12: =$U$30*G12+$V$30 -> 5.3631429 | K12: =$U$31*G12^$V$31 -> 1.0197128 | L12: =$U$32*G12^$V$32 -> 0.044313018 | M12: =$U$33*G12^$V$33 -> -144.22518 | N12: =(E12^H12)*(EXP(J12*E12*(-(E12^I12)))+(K12/E12))^(E12*L12+M12) -> 0.0012232839 | O12: =N12*G12 -> 0.00041891142
A13: 1.3.1 | B13: G | D13: 3 | E13: 5 | F13: 36.82474 | G13: =F13/100 -> 0.3682474 | H13: =$U$28*G13^$V$28 -> -145.26289 | I13: =$U$29*G13+$V$29 -> -0.83114247 | J13: =$U$30*G13+$V$30 -> 5.3757938 | K13: =$U$31*G13^$V$31 -> 1.0191663 | L13: =$U$32*G13^$V$32 -> 0.046955454 | M13: =$U$33*G13^$V$33 -> -145.53511 | N13: =(E13^H13)*(EXP(J13*E13*(-(E13^I13)))+(K13/E13))^(E13*L13+M13) -> 0.036425736 | O13: =N13*G13 -> 0.013413682 | P13: =SUM(O13:O15) -> 0.01870691 | Q13: =SUM(N13:N15) -> 0.050287205 | R13: =P13/Q13 -> 0.37200139
A14: 1.3.2 | B14: H | D14: 3 | E14: 15 | F14: 39.102898 | G14: =F14/100 -> 0.39102898 | H14: =$U$28*G14^$V$28 -> -146.34438 | I14: =$U$29*G14+$V$29 -> -0.8335801 | J14: =$U$30*G14+$V$30 -> 5.386965 | K14: =$U$31*G14^$V$31 -> 1.0187149 | L14: =$U$32*G14^$V$32 -> 0.049257737 | M14: =$U$33*G14^$V$33 -> -146.62664 | N14: =(E14^H14)*(EXP(J14*E14*(-(E14^I14)))+(K14/E14))^(E14*L14+M14) -> 0.012296465 | O14: =N14*G14 -> 0.0048082743
A15: 1.3.3 | B15: I | E15: 30 | F15: 30.987379 | G15: =F15/100 -> 0.30987379 | H15: =$U$28*G15^$V$28 -> -142.19768 | I15: =$U$29*G15+$V$29 -> -0.8248965 | J15: =$U$30*G15+$V$30 -> 5.3471697 | K15: =$U$31*G15^$V$31 -> 1.0204653 | L15: =$U$32*G15^$V$32 -> 0.040918038 | M15: =$U$33*G15^$V$33 -> -142.44178 | N15: =(E15^H15)*(EXP(J15*E15*(-(E15^I15)))+(K15/E15))^(E15*L15+M15) -> 0.0015650043 | O15: =N15*G15 -> 0.00048495381
A16: 1.4.1 | B16: J | D16: 4 | E16: 5 | F16: 43.437219 | G16: =F16/100 -> 0.43437219 | H16: =$U$28*G16^$V$28 -> -148.25775 | I16: =$U$29*G16+$V$29 -> -0.83821782 | J16: =$U$30*G16+$V$30 -> 5.4082187 | K16: =$U$31*G16^$V$31 -> 1.0179249 | L16: =$U$32*G16^$V$32 -> 0.053564811 | M16: =$U$33*G16^$V$33 -> -148.55791 | N16: =(E16^H16)*(EXP(J16*E16*(-(E16^I16)))+(K16/E16))^(E16*L16+M16) -> 0.039389225 | O16: =N16*G16 -> 0.017109584 | P16: =SUM(O16:O18) -> 0.022551319 | Q16: =SUM(N16:N18) -> 0.051675116 | R16: =P16/Q16 -> 0.43640578
A17: 1.4.2 | B17: K | D17: 4 | E17: 15 | F17: 47.373664 | G17: =F17/100 -> 0.47373664 | H17: =$U$28*G17^$V$28 -> -149.85558 | I17: =$U$29*G17+$V$29 -> -0.84242982 | J17: =$U$30*G17+$V$30 -> 5.4275215 | K17: =$U$31*G17^$V$31 -> 1.0172734 | L17: =$U$32*G17^$V$32 -> 0.057401432 | M17: =$U$33*G17^$V$33 -> -150.17082 | N17: =(E17^H17)*(EXP(J17*E17*(-(E17^I17)))+(K17/E17))^(E17*L17+M17) -> 0.010331984 | O17: =N17*G17 -> 0.0048946394
A18: 1.4.3 | B18: L | E18: 30 | F18: 28.000103 | G18: =F18/100 -> 0.28000103 | H18: =$U$28*G18^$V$28 -> -140.42755 | I18: =$U$29*G18+$V$29 -> -0.82170011 | J18: =$U$30*G18+$V$30 -> 5.3325213 | K18: =$U$31*G18^$V$31 -> 1.021229 | L18: =$U$32*G18^$V$32 -> 0.037740511 | M18: =$U$33*G18^$V$33 -> -140.65563 | N18: =(E18^H18)*(EXP(J18*E18*(-(E18^I18)))+(K18/E18))^(E18*L18+M18) -> 0.0019539065 | O18: =N18*G18 -> 0.00054709584
A19: 1.5.1 | B19: M | D19: 5 | E19: 5 | F19: 48.679085 | G19: =F19/100 -> 0.48679085 | H19: =$U$28*G19^$V$28 -> -150.35979 | I19: =$U$29*G19+$V$29 -> -0.84382662 | J19: =$U$30*G19+$V$30 -> 5.4339228 | K19: =$U$31*G19^$V$31 -> 1.0170694 | L19: =$U$32*G19^$V$32 -> 0.05865928 | M19: =$U$33*G19^$V$33 -> -150.67982 | N19: =(E19^H19)*(EXP(J19*E19*(-(E19^I19)))+(K19/E19))^(E19*L19+M19) -> 0.041422185 | O19: =N19*G19 -> 0.020163941 | P19: =SUM(O19:O21) -> 0.025443077 | Q19: =SUM(N19:N21) -> 0.053468974 | R19: =P19/Q19 -> 0.47584749
A20: 1.5.2 | B20: N | D20: 5 | E20: 15 | F20: 44.526267 | G20: =F20/100 -> 0.44526267 | H20: =$U$28*G20^$V$28 -> -148.7121 | I20: =$U$29*G20+$V$29 -> -0.83938311 | J20: =$U$30*G20+$V$30 -> 5.413559 | K20: =$U$31*G20^$V$31 -> 1.0177389 | L20: =$U$32*G20^$V$32 -> 0.054633039 | M20: =$U$33*G20^$V$33 -> -149.01653 | N20: =(E20^H20)*(EXP(J20*E20*(-(E20^I20)))+(K20/E20))^(E20*L20+M20) -> 0.011007046 | O20: =N20*G20 -> 0.0049010266
A21: 1.5.3 | B21: O | E21: 30 | F21: 36.365711 | G21: =F21/100 -> 0.36365711 | H21: =$U$28*G21^$V$28 -> -145.03791 | I21: =$U$29*G21+$V$29 -> -0.83065131 | J21: =$U$30*G21+$V$30 -> 5.3735429 | K21: =$U$31*G21^$V$31 -> 1.0192606 | L21: =$U$32*G21^$V$32 -> 0.046488118 | M21: =$U$33*G21^$V$33 -> -145.30804 | N21: =(E21^H21)*(EXP(J21*E21*(-(E21^I21)))+(K21/E21))^(E21*L21+M21) -> 0.0010397432 | O21: =N21*G21 -> 0.00037811
A22: 1.6.1 | B22: P | D22: 6 | E22: 5 | F22: 44.401891 | G22: =F22/100 -> 0.44401891 | H22: =$U$28*G22^$V$28 -> -148.66071 | I22: =$U$29*G22+$V$29 -> -0.83925002 | J22: =$U$30*G22+$V$30 -> 5.4129491 | K22: =$U$31*G22^$V$31 -> 1.0177599 | L22: =$U$32*G22^$V$32 -> 0.054511311 | M22: =$U$33*G22^$V$33 -> -148.96466 | N22: =(E22^H22)*(EXP(J22*E22*(-(E22^I22)))+(K22/E22))^(E22*L22+M22) -> 0.039783795 | O22: =N22*G22 -> 0.017664757 | P22: =SUM(O22:O24) -> 0.022776167 | Q22: =SUM(N22:N24) -> 0.054409346 | R22: =P22/Q22 -> 0.41860762
A23: 1.6.2 | B23: Q | D23: 6 | E23: 15 | F23: 35.260535 | G23: =F23/100 -> 0.35260535 | H23: =$U$28*G23^$V$28 -> -144.48584 | I23: =$U$29*G23+$V$29 -> -0.82946877 | J23: =$U$30*G23+$V$30 -> 5.3681236 | K23: =$U$31*G23^$V$31 -> 1.0194928 | L23: =$U$32*G23^$V$32 -> 0.045357996 | M23: =$U$33*G23^$V$33 -> -144.75088 | N23: =(E23^H23)*(EXP(J23*E23*(-(E23^I23)))+(K23/E23))^(E23*L23+M23) -> 0.013185271 | O23: =N23*G23 -> 0.0046491972
A24: 1.6.3 | B24: R | E24: 30 | F24: 32.091847 | G24: =F24/100 -> 0.32091847 | H24: =$U$28*G24^$V$28 -> -142.8144 | I24: =$U$29*G24+$V$29 -> -0.82607828 | J24: =$U$30*G24+$V$30 -> 5.3525856 | K24: =$U$31*G24^$V$31 -> 1.0202015 | L24: =$U$32*G24^$V$32 -> 0.042076888 | M24: =$U$33*G24^$V$33 -> -143.06412 | N24: =(E24^H24)*(EXP(J24*E24*(-(E24^I24)))+(K24/E24))^(E24*L24+M24) -> 0.0014402802 | O24: =N24*G24 -> 0.00046221254
A25: 2.1.1 | B25: S | C25: 20 | D25: 1 | E25: 5 | F25: 51.495774 | G25: =F25/100 -> 0.51495774 | H25: =$U$28*G25^$V$28 -> -151.40856 | I25: =$U$29*G25+$V$29 -> -0.84684048 | J25: =$U$30*G25+$V$30 -> 5.4477347 | K25: =$U$31*G25^$V$31 -> 1.0166472 | L25: =$U$32*G25^$V$32 -> 0.061350385 | M25: =$U$33*G25^$V$33 -> -151.73859 | N25: =(E25^H25)*(EXP(J25*E25*(-(E25^I25)))+(K25/E25))^(E25*L25+M25) -> 0.042404718 | O25: =N25*G25 -> 0.021836638 | P25: =SUM(O25:O27) -> 0.026880349 | Q25: =SUM(N25:N27) -> 0.057690783 | R25: =P25/Q25 -> 0.46593835
A26: 2.1.2 | B26: U | E26: 15 | F26: 33.358788 | G26: =F26/100 -> 0.33358788 | H26: =$U$28*G26^$V$28 -> -143.49934 | I26: =$U$29*G26+$V$29 -> -0.8274339 | J26: =$U$30*G26+$V$30 -> 5.3587982 | K26: =$U$31*G26^$V$31 -> 1.0199101 | L26: =$U$32*G26^$V$32 -> 0.043396313 | M26: =$U$33*G26^$V$33 -> -143.75532 | N26: =(E26^H26)*(EXP(J26*E26*(-(E26^I26)))+(K26/E26))^(E26*L26+M26) -> 0.01360749 | O26: =N26*G26 -> 0.0045392936
A27: 2.1.3 | B27: T | E27: 30 | F27: 30.050307 | G27: =F27/100 -> 0.30050307 | H27: =$U$28*G27^$V$28 -> -141.65914 | I27: =$U$29*G27+$V$29 -> -0.82389383 | J27: =$U$30*G27+$V$30 -> 5.3425747 | K27: =$U$31*G27^$V$31 -> 1.0206965 | L27: =$U$32*G27^$V$32 -> 0.039928255 | M27: =$U$33*G27^$V$33 -> -141.89835 | N27: =(E27^H27)*(EXP(J27*E27*(-(E27^I27)))+(K27/E27))^(E27*L27+M27) -> 0.0016785753 | O27: =N27*G27 -> 0.00050441703 | U27: p1 | V27: p2
A28: 2.2.1 | B28: V | D28: 2 | E28: 5 | F28: 53.551506 | G28: =F28/100 -> 0.53551506 | H28: =$U$28*G28^$V$28 -> -152.1427 | I28: =$U$29*G28+$V$29 -> -0.84904011 | J28: =$U$30*G28+$V$30 -> 5.4578152 | K28: =$U$31*G28^$V$31 -> 1.0163536 | L28: =$U$32*G28^$V$32 -> 0.063295624 | M28: =$U$33*G28^$V$33 -> -152.47976 | N28: =(E28^H28)*(EXP(J28*E28*(-(E28^I28)))+(K28/E28))^(E28*L28+M28) -> 0.043074857 | O28: =N28*G28 -> 0.023067235 | P28: =SUM(O28:O30) -> 0.028126675 | Q28: =SUM(N28:N30) -> 0.056116357 | R28: =P28/Q28 -> 0.50122061 | T28: F7 | U28: -164.3489 | V28: 0.12357
A29: 2.2.2 | B29: W | E29: 15 | F29: 38.588672 | G29: =F29/100 -> 0.38588672 | H29: =$U$28*G29^$V$28 -> -146.10519 | I29: =$U$29*G29+$V$29 -> -0.83302988 | J29: =$U$30*G29+$V$30 -> 5.3844434 | K29: =$U$31*G29^$V$31 -> 1.0188144 | L29: =$U$32*G29^$V$32 -> 0.048740496 | M29: =$U$33*G29^$V$33 -> -146.38522 | N29: =(E29^H29)*(EXP(J29*E29*(-(E29^I29)))+(K29/E29))^(E29*L29+M29) -> 0.012417365 | O29: =N29*G29 -> 0.0047916962 | T29: F8 | U29: -0.107 | V29: -0.79174
A30: 2.2.3 | B30: X | E30: 30 | F30: 42.898389 | G30: =F30/100 -> 0.42898389 | H30: =$U$28*G30^$V$28 -> -148.02925 | I30: =$U$29*G30+$V$29 -> -0.83764128 | J30: =$U$30*G30+$V$30 -> 5.4055765 | K30: =$U$31*G30^$V$31 -> 1.0180187 | L30: =$U$32*G30^$V$32 -> 0.053034281 | M30: =$U$33*G30^$V$33 -> -148.32725 | N30: =(E30^H30)*(EXP(J30*E30*(-(E30^I30)))+(K30/E30))^(E30*L30+M30) -> 0.00062413535 | O30: =N30*G30 -> 0.00026774401 | T30: F9 | U30: 0.49036 | V30: 5.19522
A31: 2.3.1 | B31: Y | D31: 3 | E31: 5 | F31: 51.912606 | G31: =F31/100 -> 0.51912606 | H31: =$U$28*G31^$V$28 -> -151.55947 | I31: =$U$29*G31+$V$29 -> -0.84728649 | J31: =$U$30*G31+$V$30 -> 5.4497787 | K31: =$U$31*G31^$V$31 -> 1.0165868 | L31: =$U$32*G31^$V$32 -> 0.061746065 | M31: =$U$33*G31^$V$33 -> -151.89094 | N31: =(E31^H31)*(EXP(J31*E31*(-(E31^I31)))+(K31/E31))^(E31*L31+M31) -> 0.04254377 | O31: =N31*G31 -> 0.02208558 | P31: =SUM(O31:O33) -> 0.027243202 | Q31: =SUM(N31:N33) -> 0.055906859 | R31: =P31/Q31 -> 0.48729623 | T31: F10 | U31: 1.01168 | V31: -0.00738
A32: 2.3.2 | B32: Z | E32: 15 | F32: 38.703234 | G32: =F32/100 -> 0.38703234 | H32: =$U$28*G32^$V$28 -> -146.15872 | I32: =$U$29*G32+$V$29 -> -0.83315246 | J32: =$U$30*G32+$V$30 -> 5.3850052 | K32: =$U$31*G32^$V$31 -> 1.0187921 | L32: =$U$32*G32^$V$32 -> 0.04885585 | M32: =$U$33*G32^$V$33 -> -146.43925 | N32: =(E32^H32)*(EXP(J32*E32*(-(E32^I32)))+(K32/E32))^(E32*L32+M32) -> 0.012390469 | O32: =N32*G32 -> 0.0047955123 | T32: F11 | U32: 0.10415 | V32: 0.79743
A33: 2.3.3 | B33: 1 | E33: 30 | F33: 37.230378 | G33: =F33/100 -> 0.37230378 | H33: =$U$28*G33^$V$28 -> -145.45967 | I33: =$U$29*G33+$V$29 -> -0.8315765 | J33: =$U$30*G33+$V$30 -> 5.3777829 | K33: =$U$31*G33^$V$31 -> 1.0190839 | L33: =$U$32*G33^$V$32 -> 0.047367452 | M33: =$U$33*G33^$V$33 -> -145.73371 | N33: =(E33^H33)*(EXP(J33*E33*(-(E33^I33)))+(K33/E33))^(E33*L33+M33) -> 0.00097262019 | O33: =N33*G33 -> 0.00036211017 | T33: F12 | U33: -164.80664 | V33: 0.12448
A34: 2.4.1 | B34: 2 | D34: 4 | E34: 5 | F34: 53.3733 | G34: =F34/100 -> 0.533733 | H34: =$U$28*G34^$V$28 -> -152.08005 | I34: =$U$29*G34+$V$29 -> -0.84884943 | J34: =$U$30*G34+$V$30 -> 5.4569413 | K34: =$U$31*G34^$V$31 -> 1.0163786 | L34: =$U$32*G34^$V$32 -> 0.063127602 | M34: =$U$33*G34^$V$33 -> -152.41651 | N34: =(E34^H34)*(EXP(J34*E34*(-(E34^I34)))+(K34/E34))^(E34*L34+M34) -> 0.04301831 | O34: =N34*G34 -> 0.022960292 | P34: =SUM(O34:O36) -> 0.02807435 | Q34: =SUM(N34:N36) -> 0.052741682 | R34: =P34/Q34 -> 0.5322991
A35: 2.4.2 | B35: 3 | E35: 15 | F35: 54.458165 | G35: =F35/100 -> 0.54458165 | H35: =$U$28*G35^$V$28 -> -152.45866 | I35: =$U$29*G35+$V$29 -> -0.85001024 | J35: =$U$30*G35+$V$30 -> 5.4622611 | K35: =$U$31*G35^$V$31 -> 1.0162277 | L35: =$U$32*G35^$V$32 -> 0.06414872 | M35: =$U$33*G35^$V$33 -> -152.79876 | N35: =(E35^H35)*(EXP(J35*E35*(-(E35^I35)))+(K35/E35))^(E35*L35+M35) -> 0.0087062761 | O35: =N35*G35 -> 0.0047412782
A36: 2.4.3 | B36: 4 | E36: 30 | F36: 36.651426 | G36: =F36/100 -> 0.36651426 | H36: =$U$28*G36^$V$28 -> -145.17823 | I36: =$U$29*G36+$V$29 -> -0.83095703 | J36: =$U$30*G36+$V$30 -> 5.3749439 | K36: =$U$31*G36^$V$31 -> 1.0192018 | L36: =$U$32*G36^$V$32 -> 0.046779143 | M36: =$U$33*G36^$V$33 -> -145.44967 | N36: =(E36^H36)*(EXP(J36*E36*(-(E36^I36)))+(K36/E36))^(E36*L36+M36) -> 0.0010170954 | O36: =N36*G36 -> 0.00037277996
A37: 2.5.1 | B37: 5 | D37: 5 | E37: 5 | F37: 65.193437 | G37: =F37/100 -> 0.65193437 | H37: =$U$28*G37^$V$28 -> -155.88631 | I37: =$U$29*G37+$V$29 -> -0.86149698 | J37: =$U$30*G37+$V$30 -> 5.5149025 | K37: =$U$31*G37^$V$31 -> 1.0148792 | L37: =$U$32*G37^$V$32 -> 0.074045705 | M37: =$U$33*G37^$V$33 -> -156.25963 | N37: =(E37^H37)*(EXP(J37*E37*(-(E37^I37)))+(K37/E37))^(E37*L37+M37) -> 0.046158264 | O37: =N37*G37 -> 0.030092159 | P37: =SUM(O37:O39) -> 0.035219976 | Q37: =SUM(N37:N39) -> 0.057696708 | R37: =P37/Q37 -> 0.61043303
A38: 2.5.2 | B38: 6 | E38: 15 | F38: 44.38183 | G38: =F38/100 -> 0.4438183 | H38: =$U$28*G38^$V$28 -> -148.65241 | I38: =$U$29*G38+$V$29 -> -0.83922856 | J38: =$U$30*G38+$V$30 -> 5.4128507 | K38: =$U$31*G38^$V$31 -> 1.0177633 | L38: =$U$32*G38^$V$32 -> 0.05449167 | M38: =$U$33*G38^$V$33 -> -148.95628 | N38: =(E38^H38)*(EXP(J38*E38*(-(E38^I38)))+(K38/E38))^(E38*L38+M38) -> 0.011041446 | O38: =N38*G38 -> 0.0049003959
A39: 2.5.3 | B39: 7 | E39: 30 | F39: 45.759082 | G39: =F39/100 -> 0.45759082 | H39: =$U$28*G39^$V$28 -> -149.21483 | I39: =$U$29*G39+$V$29 -> -0.84070222 | J39: =$U$30*G39+$V$30 -> 5.4196042 | K39: =$U$31*G39^$V$31 -> 1.0175338 | L39: =$U$32*G39^$V$32 -> 0.055835922 | M39: =$U$33*G39^$V$33 -> -149.524 | N39: =(E39^H39)*(EXP(J39*E39*(-(E39^I39)))+(K39/E39))^(E39*L39+M39) -> 0.00049699747 | O39: =N39*G39 -> 0.00022742148
A40: 3.1.1 | B40: 8 | C40: 50 | D40: 1 | E40: 5 | F40: 65.060853 | G40: =F40/100 -> 0.65060853 | H40: =$U$28*G40^$V$28 -> -155.8471 | I40: =$U$29*G40+$V$29 -> -0.86135511 | J40: =$U$30*G40+$V$30 -> 5.5142524 | K40: =$U$31*G40^$V$31 -> 1.0148944 | L40: =$U$32*G40^$V$32 -> 0.073925598 | M40: =$U$33*G40^$V$33 -> -156.22004 | N40: =(E40^H40)*(EXP(J40*E40*(-(E40^I40)))+(K40/E40))^(E40*L40+M40) -> 0.046129693 | O40: =N40*G40 -> 0.030012371 | P40: =SUM(O40:O42) -> 0.035185043 | Q40: =SUM(N40:N42) -> 0.058493155 | R40: =P40/Q40 -> 0.60152411
A41: 3.1.2 | B41: 9 | E41: 15 | F41: 41.895742 | G41: =F41/100 -> 0.41895742 | H41: =$U$28*G41^$V$28 -> -147.59727 | I41: =$U$29*G41+$V$29 -> -0.83656844 | J41: =$U$30*G41+$V$30 -> 5.40066 | K41: =$U$31*G41^$V$31 -> 1.0181964 | L41: =$U$32*G41^$V$32 -> 0.052043465 | M41: =$U$33*G41^$V$33 -> -147.89123 | N41: =(E41^H41)*(EXP(J41*E41*(-(E41^I41)))+(K41/E41))^(E41*L41+M41) -> 0.011634123 | O41: =N41*G41 -> 0.0048742023 | T41: rbulk / g cm-3 | V41: Hveg/ kgm-2 | X41: p / mbar | AC41: -0.85705646
A42: 3.1.3 | B42: 10 | E42: 30 | F42: 40.923271 | G42: =F42/100 -> 0.40923271 | H42: =$U$28*G42^$V$28 -> -147.16956 | I42: =$U$29*G42+$V$29 -> -0.8355279 | J42: =$U$30*G42+$V$30 -> 5.3958914 | K42: =$U$31*G42^$V$31 -> 1.0183729 | L42: =$U$32*G42^$V$32 -> 0.051077871 | M42: =$U$33*G42^$V$33 -> -147.45951 | N42: =(E42^H42)*(EXP(J42*E42*(-(E42^I42)))+(K42/E42))^(E42*L42+M42) -> 0.00072933904 | O42: =N42*G42 -> 0.00029846939 | T42: =18/9.81 -> 1.8348624 | V42: 1.54 | X42: 995.25
A43: 3.2.1 | B43: 11 | D43: 2 | E43: 5 | F43: 54.071375 | G43: =F43/100 -> 0.54071375 | H43: =$U$28*G43^$V$28 -> -152.32444 | I43: =$U$29*G43+$V$29 -> -0.84959637 | J43: =$U$30*G43+$V$30 -> 5.4603644 | K43: =$U$31*G43^$V$31 -> 1.0162811 | L43: =$U$32*G43^$V$32 -> 0.063785135 | M43: =$U$33*G43^$V$33 -> -152.66324 | N43: =(E43^H43)*(EXP(J43*E43*(-(E43^I43)))+(K43/E43))^(E43*L43+M43) -> 0.043238153 | O43: =N43*G43 -> 0.023379464 | P43: =SUM(O43:O45) -> 0.028563284 | Q43: =SUM(N43:N45) -> 0.056170926 | R43: =P43/Q43 -> 0.50850656
A44: 3.2.2 | B44: 12 | E44: 15 | F44: 40.222331 | G44: =F44/100 -> 0.40222331 | H44: =$U$28*G44^$V$28 -> -146.8557 | I44: =$U$29*G44+$V$29 -> -0.83477789 | J44: =$U$30*G44+$V$30 -> 5.3924542 | K44: =$U$31*G44^$V$31 -> 1.0185027 | L44: =$U$32*G44^$V$32 -> 0.050379005 | M44: =$U$33*G44^$V$33 -> -147.14272 | N44: =(E44^H44)*(EXP(J44*E44*(-(E44^I44)))+(K44/E44))^(E44*L44+M44) -> 0.012031925 | O44: =N44*G44 -> 0.0048395207
...

Sheet Ponderação Horizontal 
L5: Método 1
A6: Amostra | B6: Cápsulas | C6: Raio / m | D6: Perfil | E6: Profundidade / cm | F6: ϑV | G6: θp | H6: Fp | I6: Fveg | J6: r* | K6: r* novo | L6: F1 | M6: F2 | N6: F3 | O6: F4 | P6: F5 | Q6: F6 | R6: Wr (h, ϑ) | S6: ϑp * Wr (r, ϑ) | T6: ∑ (ϑp * Wr (r, ϑ)) | U6: ∑ (Wr (r, ϑ))
A7: 1.1.1 | B7: A | C7: 2 | D7: 1 | E7: 5 | F7: 0.61043419 | G7: 0.53132467 | H7: 1.0135545 | I7: 0.92013302 | J7: =$C$7/H7/I7 -> 2.1445307 | K7: =C7*((0.5/(0.86-EXP(-X43/1012)))^-1) -> 1.9439239 | L7: =$W$28*G7+$X$28 -> 17.325864 | M7: =$W$29*G7+$X$29 -> -0.32641375 | N7: =$W$30*G7+$X$30 -> 1.5340581 | O7: =$W$31*G7^$X$31 -> 1.4383773 | P7: =$W$32*G7^$X$32 -> 0.007720073 | Q7: =$W$33*G7+$X$33 -> 17.33626 | R7: =(J7^L7)*(EXP(-(J7^M7)*N7*J7)+(O7/J7))^(J7*P7+Q7) -> 3540.8272 | S7: =G7*R7 -> 1881.3288 | T7: =SUM(S7:S48) -> 29894.336 | U7: =SUM(R7:R48) -> 66628.925 | V7: =T7/U7 -> 0.44866904
A8: 1.1.2 | B8: B | E8: 15 | F8: 0.2982845 | H8: 1.0135545 | I8: 0.86076167 | J8: =$C$7/H8/I8 -> 2.2924505 | R8: =(J8^L7)*(EXP(-(J8^M7)*N7*J8)+(O7/J8))^(J8*P7+Q7) -> 3231.2319 | S8: =G7*R8 -> 1716.8332
A9: 1.1.3 | B9: C | E9: 30 | F9: 0.34171519 | H9: 1.0135545 | I9: 0.84082788 | J9: =$C$7/H9/I9 -> 2.3467984 | R9: =(J9^L7)*(EXP(-(J9^M7)*N7*J9)+(O7/J9))^(J9*P7+Q7) -> 3125.2207 | S9: =G7*R9 -> 1660.5069
A10: 1.2.1 | B10: D | D10: 2 | E10: 5 | F10: 0.42832892 | G10: 0.42202829 | H10: 1.0135545 | I10: 0.84082788 | J10: =$C$7/H10/I10 -> 2.3467984 | L10: =$W$28*G10+$X$28 -> 17.533889 | M10: =$W$29*G10+$X$29 -> -0.33053531 | N10: =$W$30*G10+$X$30 -> 1.5387054 | O10: =$W$31*G10^$X$31 -> 1.4372018 | P10: =$W$32*G10^$X$32 -> 0.0077383897 | Q10: =$W$33*G10+$X$33 -> 17.540324 | R10: =(J10^L10)*(EXP(-(J10^M10)*N10*J10)+(O10/J10))^(J10*P10+Q10) -> 3411.262 | S10: =G10*R10 -> 1439.6491
A11: 1.2.2 | B11: E | D11: 2 | E11: 15 | F11: 0.40944533 | H11: 1.0135545 | I11: 0.84082788 | J11: =$C$7/H11/I11 -> 2.3467984 | R11: =(J11^L10)*(EXP(-(J11^M10)*N10*J11)+(O10/J11))^(J11*P10+Q10) -> 3411.262 | S11: =G10*R11 -> 1439.6491
A12: 1.2.3 | B12: F | E12: 30 | F12: 0.34244825 | H12: 1.0135545 | I12: 0.84082788 | J12: =$C$7/H12/I12 -> 2.3467984 | R12: =(J12^L10)*(EXP(-(J12^M10)*N10*J12)+(O10/J12))^(J12*P10+Q10) -> 3411.262 | S12: =G10*R12 -> 1439.6491
A13: 1.3.1 | B13: G | D13: 3 | E13: 5 | F13: 0.3682474 | G13: 0.37200139 | H13: 1.0135545 | I13: 0.84082788 | J13: =$C$7/H13/I13 -> 2.3467984 | L13: =$W$28*G13+$X$28 -> 17.629106 | M13: =$W$29*G13+$X$29 -> -0.33242183 | N13: =$W$30*G13+$X$30 -> 1.5408325 | O13: =$W$31*G13^$X$31 -> 1.4365582 | P13: =$W$32*G13^$X$32 -> 0.0077484433 | Q13: =$W$33*G13+$X$33 -> 17.633727 | R13: =(J13^L13)*(EXP(-(J13^M13)*N13*J13)+(O13/J13))^(J13*P13+Q13) -> 3546.3708 | S13: =G13*R13 -> 1319.2549
A14: 1.3.2 | B14: H | D14: 3 | E14: 15 | F14: 0.39102898 | H14: 1.0135545 | I14: 0.84082788 | J14: =$C$7/H14/I14 -> 2.3467984 | R14: =(J14^L13)*(EXP(-(J14^M13)*N13*J14)+(O13/J14))^(J14*P13+Q13) -> 3546.3708 | S14: =G13*R14 -> 1319.2549
A15: 1.3.3 | B15: I | E15: 30 | F15: 0.30987379 | H15: 1.0135545 | I15: 0.84082788 | J15: =$C$7/H15/I15 -> 2.3467984 | R15: =(J15^L13)*(EXP(-(J15^M13)*N13*J15)+(O13/J15))^(J15*P13+Q13) -> 3546.3708 | S15: =G13*R15 -> 1319.2549
A16: 1.4.1 | B16: J | D16: 4 | E16: 5 | F16: 0.43437219 | G16: 0.43640578 | H16: 1.0135545 | I16: 0.84082788 | J16: =$C$7/H16/I16 -> 2.3467984 | L16: =$W$28*G16+$X$28 -> 17.506525 | M16: =$W$29*G16+$X$29 -> -0.32999314 | N16: =$W$30*G16+$X$30 -> 1.538094 | O16: =$W$31*G16^$X$31 -> 1.4373727 | P16: =$W$32*G16^$X$32 -> 0.0077357227 | Q16: =$W$33*G16+$X$33 -> 17.51348 | R16: =(J16^L16)*(EXP(-(J16^M16)*N16*J16)+(O16/J16))^(J16*P16+Q16) -> 3372.8353 | S16: =G16*R16 -> 1471.9248
A17: 1.4.2 | B17: K | D17: 4 | E17: 15 | F17: 0.47373664 | H17: 1.0135545 | I17: 0.84082788 | J17: =$C$7/H17/I17 -> 2.3467984 | R17: =(J17^L16)*(EXP(-(J17^M16)*N16*J17)+(O16/J17))^(J17*P16+Q16) -> 3372.8353 | S17: =G16*R17 -> 1471.9248
A18: 1.4.3 | B18: L | E18: 30 | F18: 0.28000103 | H18: 1.0135545 | I18: 0.84082788 | J18: =$C$7/H18/I18 -> 2.3467984 | R18: =(J18^L16)*(EXP(-(J18^M16)*N16*J18)+(O16/J18))^(J18*P16+Q16) -> 3372.8353 | S18: =G16*R18 -> 1471.9248
A19: 1.5.1 | B19: M | D19: 5 | E19: 5 | F19: 0.48679085 | G19: 0.47584749 | H19: 1.0135545 | I19: 0.84082788 | J19: =$C$7/H19/I19 -> 2.3467984 | L19: =$W$28*G19+$X$28 -> 17.431455 | M19: =$W$29*G19+$X$29 -> -0.32850579 | N19: =$W$30*G19+$X$30 -> 1.536417 | O19: =$W$31*G19^$X$31 -> 1.4378143 | P19: =$W$32*G19^$X$32 -> 0.0077288383 | Q19: =$W$33*G19+$X$33 -> 17.439839 | R19: =(J19^L19)*(EXP(-(J19^M19)*N19*J19)+(O19/J19))^(J19*P19+Q19) -> 3268.575 | S19: =G19*R19 -> 1555.3432
A20: 1.5.2 | B20: N | D20: 5 | E20: 15 | F20: 0.44526267 | H20: 1.0135545 | I20: 0.84082788 | J20: =$C$7/H20/I20 -> 2.3467984 | R20: =(J20^L19)*(EXP(-(J20^M19)*N19*J20)+(O19/J20))^(J20*P19+Q19) -> 3268.575 | S20: =G19*R20 -> 1555.3432
A21: 1.5.3 | B21: O | E21: 30 | F21: 0.36365711 | H21: 1.0135545 | I21: 0.84082788 | J21: =$C$7/H21/I21 -> 2.3467984 | R21: =(J21^L19)*(EXP(-(J21^M19)*N19*J21)+(O19/J21))^(J21*P19+Q19) -> 3268.575 | S21: =G19*R21 -> 1555.3432
A22: 1.6.1 | B22: P | D22: 6 | E22: 5 | F22: 0.44401891 | G22: 0.41860762 | H22: 1.0135545 | I22: 0.84082788 | J22: =$C$7/H22/I22 -> 2.3467984 | L22: =$W$28*G22+$X$28 -> 17.5404 | M22: =$W$29*G22+$X$29 -> -0.33066431 | N22: =$W$30*G22+$X$30 -> 1.5388508 | O22: =$W$31*G22^$X$31 -> 1.4371603 | P22: =$W$32*G22^$X$32 -> 0.0077390378 | Q22: =$W$33*G22+$X$33 -> 17.54671 | R22: =(J22^L22)*(EXP(-(J22^M22)*N22*J22)+(O22/J22))^(J22*P22+Q22) -> 3420.4343 | S22: =G22*R22 -> 1431.8199
A23: 1.6.2 | B23: Q | D23: 6 | E23: 15 | F23: 0.35260535 | H23: 1.0135545 | I23: 0.84082788 | J23: =$C$7/H23/I23 -> 2.3467984 | R23: =(J23^L22)*(EXP(-(J23^M22)*N22*J23)+(O22/J23))^(J23*P22+Q22) -> 3420.4343 | S23: =G22*R23 -> 1431.8199
A24: 1.6.3 | B24: R | E24: 30 | F24: 0.32091847 | H24: 1.0135545 | I24: 0.84082788 | J24: =$C$7/H24/I24 -> 2.3467984 | R24: =(J24^L22)*(EXP(-(J24^M22)*N22*J24)+(O22/J24))^(J24*P22+Q22) -> 3420.4343 | S24: =G22*R24 -> 1431.8199
A25: 2.1.1 | B25: S | C25: 20 | D25: 1 | E25: 5 | F25: 0.51495774 | G25: 0.46593835 | H25: 1.0135545 | I25: 0.84082788 | J25: =$C$25/H25/I25 -> 23.467984 | K25: =C25*((0.5/(0.86-EXP(-X43/1012)))^-1) -> 19.439239 | L25: =$W$28*G25+$X$28 -> 17.450315 | M25: =$W$29*G25+$X$29 -> -0.32887946 | N25: =$W$30*G25+$X$30 -> 1.5368383 | O25: =$W$31*G25^$X$31 -> 1.4377069 | P25: =$W$32*G25^$X$32 -> 0.0077305121 | Q25: =$W$33*G25+$X$33 -> 17.45834 | R25: =(J25^L25)*(EXP(-(J25^M25)*N25*J25)+(O25/J25))^(J25*P25+Q25) -> 332.65261 | S25: =G25*R25 -> 154.99561
A26: 2.1.2 | B26: U | E26: 15 | F26: 0.33358788 | H26: 1.0135545 | I26: 0.84082788 | J26: =$C$25/H26/I26 -> 23.467984 | R26: =(J26^L25)*(EXP(-(J26^M25)*N25*J26)+(O25/J26))^(J26*P25+Q25) -> 332.65261 | S26: =G25*R26 -> 154.99561
A27: 2.1.3 | B27: T | E27: 30 | F27: 0.30050307 | H27: 1.0135545 | I27: 0.84082788 | J27: =$C$25/H27/I27 -> 23.467984 | R27: =(J27^L25)*(EXP(-(J27^M25)*N25*J27)+(O25/J27))^(J27*P25+Q25) -> 332.65261 | S27: =G25*R27 -> 154.99561 | W27: p1 | X27: p2
A28: 2.2.1 | B28: V | D28: 2 | E28: 5 | F28: 0.53551506 | G28: 0.50122061 | H28: 1.0135545 | I28: 0.84082788 | J28: =$C$25/H28/I28 -> 23.467984 | L28: =$W$28*G28+$X$28 -> 17.383162 | M28: =$W$29*G28+$X$29 -> -0.32754897 | N28: =$W$30*G28+$X$30 -> 1.5353381 | O28: =$W$31*G28^$X$31 -> 1.4380795 | P28: =$W$32*G28^$X$32 -> 0.0077247079 | Q28: =$W$33*G28+$X$33 -> 17.392466 | R28: =(J28^L28)*(EXP(-(J28^M28)*N28*J28)+(O28/J28))^(J28*P28+Q28) -> 325.07188 | S28: =G28*R28 -> 162.93273 | V28: F1 | W28: -1.90331 | X28: 18.33714
A29: 2.2.2 | B29: W | E29: 15 | F29: 0.38588672 | H29: 1.0135545 | I29: 0.84082788 | J29: =$C$25/H29/I29 -> 23.467984 | R29: =(J29^L28)*(EXP(-(J29^M28)*N28*J29)+(O28/J29))^(J29*P28+Q28) -> 325.07188 | S29: =G28*R29 -> 162.93273 | V29: F2 | W29: 0.03771 | X29: -0.34645
A30: 2.2.3 | B30: X | E30: 30 | F30: 0.42898389 | H30: 1.0135545 | I30: 0.84082788 | J30: =$C$25/H30/I30 -> 23.467984 | R30: =(J30^L28)*(EXP(-(J30^M28)*N28*J30)+(O28/J30))^(J30*P28+Q28) -> 325.07188 | S30: =G28*R30 -> 162.93273 | V30: F3 | W30: -0.04252 | X30: 1.55665
A31: 2.3.1 | B31: Y | D31: 3 | E31: 5 | F31: 0.51912606 | G31: 0.48729623 | H31: 1.0135545 | I31: 0.84082788 | J31: =$C$25/H31/I31 -> 23.467984 | L31: =$W$28*G31+$X$28 -> 17.409664 | M31: =$W$29*G31+$X$29 -> -0.32807406 | N31: =$W$30*G31+$X$30 -> 1.5359302 | O31: =$W$31*G31^$X$31 -> 1.4379357 | P31: =$W$32*G31^$X$32 -> 0.0077269477 | Q31: =$W$33*G31+$X$33 -> 17.418464 | R31: =(J31^L31)*(EXP(-(J31^M31)*N31*J31)+(O31/J31))^(J31*P31+Q31) -> 328.05816 | S31: =G31*R31 -> 159.8615 | V31: F4 | W31: 1.44161 | X31: 0.00355
A32: 2.3.2 | B32: Z | E32: 15 | F32: 0.38703234 | H32: 1.0135545 | I32: 0.84082788 | J32: =$C$25/H32/I32 -> 23.467984 | R32: =(J32^L31)*(EXP(-(J32^M31)*N31*J32)+(O31/J32))^(J32*P31+Q31) -> 328.05816 | S32: =G31*R32 -> 159.8615 | V32: F5 | W32: 0.00767 | X32: -0.01029
A33: 2.3.3 | B33: 1 | E33: 30 | F33: 0.37230378 | H33: 1.0135545 | I33: 0.84082788 | J33: =$C$25/H33/I33 -> 23.467984 | R33: =(J33^L31)*(EXP(-(J33^M31)*N31*J33)+(O31/J33))^(J33*P31+Q31) -> 328.05816 | S33: =G31*R33 -> 159.8615 | V33: F6 | W33: -1.86707 | X33: 18.32828
A34: 2.4.1 | B34: 2 | D34: 4 | E34: 5 | F34: 0.533733 | G34: 0.5322991 | H34: 1.0135545 | I34: 0.84082788 | J34: =$C$25/H34/I34 -> 23.467984 | L34: =$W$28*G34+$X$28 -> 17.32401 | M34: =$W$29*G34+$X$29 -> -0.326377 | N34: =$W$30*G34+$X$30 -> 1.5340166 | O34: =$W$31*G34^$X$31 -> 1.4383866 | P34: =$W$32*G34^$X$32 -> 0.0077199275 | Q34: =$W$33*G34+$X$33 -> 17.33444 | R34: =(J34^L34)*(EXP(-(J34^M34)*N34*J34)+(O34/J34))^(J34*P34+Q34) -> 318.44012 | S34: =G34*R34 -> 169.50539
A35: 2.4.2 | B35: 3 | E35: 15 | F35: 0.54458165 | H35: 1.0135545 | I35: 0.84082788 | J35: =$C$25/H35/I35 -> 23.467984 | R35: =(J35^L34)*(EXP(-(J35^M34)*N34*J35)+(O34/J35))^(J35*P34+Q34) -> 318.44012 | S35: =G34*R35 -> 169.50539
A36: 2.4.3 | B36: 4 | E36: 30 | F36: 0.36651426 | H36: 1.0135545 | I36: 0.84082788 | J36: =$C$25/H36/I36 -> 23.467984 | R36: =(J36^L34)*(EXP(-(J36^M34)*N34*J36)+(O34/J36))^(J36*P34+Q34) -> 318.44012 | S36: =G34*R36 -> 169.50539
A37: 2.5.1 | B37: 5 | D37: 5 | E37: 5 | F37: 0.65193437 | G37: 0.61043303 | H37: 1.0135545 | I37: 0.84082788 | J37: =$C$25/H37/I37 -> 23.467984 | L37: =$W$28*G37+$X$28 -> 17.175297 | M37: =$W$29*G37+$X$29 -> -0.32343057 | N37: =$W$30*G37+$X$30 -> 1.5306944 | O37: =$W$31*G37^$X$31 -> 1.4390862 | P37: =$W$32*G37^$X$32 -> 0.0077090551 | Q37: =$W$33*G37+$X$33 -> 17.188559 | R37: =(J37^L37)*(EXP(-(J37^M37)*N37*J37)+(O37/J37))^(J37*P37+Q37) -> 302.03833 | S37: =G37*R37 -> 184.37417
A38: 2.5.2 | B38: 6 | E38: 15 | F38: 0.4438183 | H38: 1.0135545 | I38: 0.84082788 | J38: =$C$25/H38/I38 -> 23.467984 | R38: =(J38^L37)*(EXP(-(J38^M37)*N37*J38)+(O37/J38))^(J38*P37+Q37) -> 302.03833 | S38: =G37*R38 -> 184.37417
A39: 2.5.3 | B39: 7 | E39: 30 | F39: 0.45759082 | H39: 1.0135545 | I39: 0.84082788 | J39: =$C$25/H39/I39 -> 23.467984 | R39: =(J39^L37)*(EXP(-(J39^M37)*N37*J39)+(O37/J39))^(J39*P37+Q37) -> 302.03833 | S39: =G37*R39 -> 184.37417
A40: 3.1.1 | B40: 8 | C40: 50 | D40: 1 | E40: 5 | F40: 0.65060853 | G40: 0.60152411 | H40: 1.0135545 | I40: 0.84082788 | J40: =$C$40/H40/I40 -> 58.66996 | K40: =C40*((0.5/(0.86-EXP(-X43/1012)))^-1) -> 48.598098 | L40: =$W$28*G40+$X$28 -> 17.192253 | M40: =$W$29*G40+$X$29 -> -0.32376653 | N40: =$W$30*G40+$X$30 -> 1.5310732 | O40: =$W$31*G40^$X$31 -> 1.4390111 | P40: =$W$32*G40^$X$32 -> 0.0077102214 | Q40: =$W$33*G40+$X$33 -> 17.205192 | R40: =(J40^L40)*(EXP(-(J40^M40)*N40*J40)+(O40/J40))^(J40*P40+Q40) -> 92.936398 | S40: =G40*R40 -> 55.903484
A41: 3.1.2 | B41: 9 | E41: 15 | F41: 0.41895742 | H41: 1.0135545 | I41: 0.84082788 | J41: =$C$40/H41/I41 -> 58.66996 | R41: =(J41^L40)*(EXP(-(J41^M40)*N40*J41)+(O40/J41))^(J41*P40+Q40) -> 92.936398 | S41: =G40*R41 -> 55.903484
A42: 3.1.3 | B42: 10 | E42: 30 | F42: 0.40923271 | H42: 1.0135545 | I42: 0.84082788 | J42: =$C$40/H42/I42 -> 58.66996 | R42: =(J42^L40)*(EXP(-(J42^M40)*N40*J42)+(O40/J42))^(J42*P40+Q40) -> 92.936398 | S42: =G40*R42 -> 55.903484 | W42: rbulk / g cm-3 | X42: p / mbar | Y42: H / gm-3
A43: 3.2.1 | B43: 11 | D43: 2 | E43: 5 | F43: 0.54071375 | G43: 0.50850656 | H43: 1.0135545 | I43: 0.84082788 | J43: =$C$40/H43/I43 -> 58.66996 | L43: =$W$28*G43+$X$28 -> 17.369294 | M43: =$W$29*G43+$X$29 -> -0.32727422 | N43: =$W$30*G43+$X$30 -> 1.5350283 | O43: =$W$31*G43^$X$31 -> 1.4381532 | P43: =$W$32*G43^$X$32 -> 0.0077235608 | Q43: =$W$33*G43+$X$33 -> 17.378863 | R43: =(J43^L43)*(EXP(-(J43^M43)*N43*J43)+(O43/J43))^(J43*P43+Q43) -> 99.019202 | S43: =G43*R43 -> 50.351914 | W43: =18/9.81 -> 1.8348624 | X43: 995.25 | Y43: 10.21
A44: 3.2.2 | B44: 12 | E44: 15 | F44: 0.40222331 | H44: 1.0135545 | I44: 0.84082788 | J44: =$C$40/H44/I44 -> 58.66996 | R44: =(J44^L43)*(EXP(-(J44^M43)*N43*J44)+(O43/J44))^(J44*P43+Q43) -> 99.019202 | S44: =G43*R44 -> 50.351914
...

Sheet Fatores de Correção
B2: Correção intensidade dos neutrões | F2: Dados retirados no dia 28/01/2026, desde as 11:29 às 12:29 | L2: Correção humidade do ar | R2: Correção pressão barométrica | W2: Correção da biomassa
F3: Monitor de neutrões: Jungfraujoch
M7: αhum / m3/g | N7: habs / gm-3 | O7: habsref / g/m3 | S7: λatm g/m3 | T7: Xref / g/cm2
M8: 0.0054 | N8: 10.21 | O8: 12 | S8: 132 | T8: 1000 | X8: AGB / kgm-2 | Z8: Cveg
C9: p / hPa | D9: c0 | E9: c1 | F9: c2 | G9: c3 | H9: c4 | I9: c5 | X9: 1.54 | Z9: =1/(1-0.009*X9) -> 1.0140548
C10: =(995.6+994.9)/2 -> 995.25 | D10: 0.0009 | E10: 1.7699 | F10: 0.0064 | G10: 1.8855 | H10: 1.3e-05 | I10: 1.2237 | M10: Ch | S10: Cp
M11: =1+M8*(N8-O8) -> 0.990334 | S11: =EXP((C16-T8)/S8) -> 1.1163288
C15: X / g/cm2 | D15: Rc / GV | E15: K (Jungfraujoch) | F15: ε | G15: τ
C16: =(C10*100/9.81)/10 -> 1014.526 | D16: 6.9 | E16: 1.36 | F16: 1 | G16: =F16*E16*(-D10*C16+E10)*(1-EXP(-(F10*C16+G10)*D16^(H10*C16-I10))) -> 0.64616665
C19: I / cont/s | D19: Iref / cont/s | E19: CI
C20: 140.52 | D20: 156.17 | E20: =(C20*G16/D20+1-G16)^-1 -> 1.0692365

Sheet Método N0
B2: Dados retirados no dia 28/01/2026, desde as 11:29 às 12:29
C4: Contagens 23:30 | D4: Contagens 22:30 | E4: N | F4: CI | G4: Ch | H4: Cp | I4: Cveg | J4: Ncorr | K4: a0 | L4: a1 | M4: a2 | N4: N0
